<?xml version="1.0" ?>
<robot name="mars_rover">
  <link name="base_link">
    <visual>
      <origin xyz="0 0 0" rpy="0 0 0"/>
      <geometry>
        <box size="0.5 0.3 0.12"/>
      </geometry>
      <material name="orange">
        <color rgba="0.85 0.45 0.1 1"/>
      </material>
    </visual>
    <collision>
      <origin xyz="0 0 0" rpy="0 0 0"/>
      <geometry>
        <box size="0.5 0.3 0.12"/>
      </geometry>
    </collision>
    <inertial>
      <origin xyz="0 0 0" rpy="0 0 0"/>
      <mass value="3.0"/>
      <inertia ixx="0.0261" iyy="0.0661" izz="0.085" ixy="0" ixz="0" iyz="0"/>
    </inertial>
  </link>
  <link name="mast_link">
    <visual>
      <origin xyz="0 0 0.1" rpy="0 0 0"/>
      <geometry>
        <cylinder radius="0.02" length="0.20"/>
      </geometry>
      <material name="white">
        <color rgba="0.9 0.9 0.9 1"/>
      </material>
    </visual>
    <inertial>
      <origin xyz="0 0 0" rpy="0 0 0"/>
      <mass value="0.1"/>
      <inertia ixx="0.000343" iyy="0.000343" izz="2e-05" ixy="0" ixz="0" iyz="0"/>
    </inertial>
  </link>
  <link name="rocker_left">
    <visual>
      <origin xyz="0 0.11 0" rpy="0 0 0"/>
      <geometry>
        <cylinder radius="0.015" length="0.22"/>
      </geometry>
      <material name="silver">
        <color rgba="0.7 0.7 0.7 1"/>
      </material>
    </visual>
    <collision>
      <origin xyz="0 0.11 0" rpy="0 0 0"/>
      <geometry>
        <cylinder radius="0.015" length="0.22"/>
      </geometry>
    </collision>
    <inertial>
      <origin xyz="0 0 0" rpy="0 0 0"/>
      <mass value="0.15"/>
      <inertia ixx="0.000613" iyy="0.000613" izz="1.7e-05" ixy="0" ixz="0" iyz="0"/>
    </inertial>
  </link>
  <link name="bogie_left">
    <visual>
      <origin xyz="0 0.09 0" rpy="0 0 0"/>
      <geometry>
        <cylinder radius="0.015" length="0.18"/>
      </geometry>
      <material name="silver">
        <color rgba="0.7 0.7 0.7 1"/>
      </material>
    </visual>
    <collision>
      <origin xyz="0 0.09 0" rpy="0 0 0"/>
      <geometry>
        <cylinder radius="0.015" length="0.18"/>
      </geometry>
    </collision>
    <inertial>
      <origin xyz="0 0 0" rpy="0 0 0"/>
      <mass value="0.15"/>
      <inertia ixx="0.000413" iyy="0.000413" izz="1.7e-05" ixy="0" ixz="0" iyz="0"/>
    </inertial>
  </link>
  <link name="wheel_front_left">
    <visual>
      <origin xyz="0 0 0" rpy="1.5708 0 0"/>
      <geometry>
        <cylinder radius="0.07" length="0.05"/>
      </geometry>
      <material name="rubber">
        <color rgba="0.15 0.15 0.15 1"/>
      </material>
    </visual>
    <visual>
      <origin xyz="0 0 0" rpy="1.5708 0 0"/>
      <geometry>
        <cylinder radius="0.076" length="0.025"/>
      </geometry>
      <material name="tread">
        <color rgba="0.08 0.08 0.08 1"/>
      </material>
    </visual>
    <collision>
      <origin xyz="0 0 0" rpy="1.5708 0 0"/>
      <geometry>
        <cylinder radius="0.07" length="0.05"/>
      </geometry>
    </collision>
    <inertial>
      <origin xyz="0 0 0" rpy="0 0 0"/>
      <mass value="0.4"/>
      <inertia ixx="0.000573" iyy="0.000573" izz="0.00098" ixy="0" ixz="0" iyz="0"/>
    </inertial>
  </link>
  <link name="wheel_mid_left">
    <visual>
      <origin xyz="0 0 0" rpy="1.5708 0 0"/>
      <geometry>
        <cylinder radius="0.07" length="0.05"/>
      </geometry>
      <material name="rubber">
        <color rgba="0.15 0.15 0.15 1"/>
      </material>
    </visual>
    <visual>
      <origin xyz="0 0 0" rpy="1.5708 0 0"/>
      <geometry>
        <cylinder radius="0.076" length="0.025"/>
      </geometry>
      <material name="tread">
        <color rgba="0.08 0.08 0.08 1"/>
      </material>
    </visual>
    <collision>
      <origin xyz="0 0 0" rpy="1.5708 0 0"/>
      <geometry>
        <cylinder radius="0.07" length="0.05"/>
      </geometry>
    </collision>
    <inertial>
      <origin xyz="0 0 0" rpy="0 0 0"/>
      <mass value="0.4"/>
      <inertia ixx="0.000573" iyy="0.000573" izz="0.00098" ixy="0" ixz="0" iyz="0"/>
    </inertial>
  </link>
  <link name="wheel_rear_left">
    <visual>
      <origin xyz="0 0 0" rpy="1.5708 0 0"/>
      <geometry>
        <cylinder radius="0.07" length="0.05"/>
      </geometry>
      <material name="rubber">
        <color rgba="0.15 0.15 0.15 1"/>
      </material>
    </visual>
    <visual>
      <origin xyz="0 0 0" rpy="1.5708 0 0"/>
      <geometry>
        <cylinder radius="0.076" length="0.025"/>
      </geometry>
      <material name="tread">
        <color rgba="0.08 0.08 0.08 1"/>
      </material>
    </visual>
    <collision>
      <origin xyz="0 0 0" rpy="1.5708 0 0"/>
      <geometry>
        <cylinder radius="0.07" length="0.05"/>
      </geometry>
    </collision>
    <inertial>
      <origin xyz="0 0 0" rpy="0 0 0"/>
      <mass value="0.4"/>
      <inertia ixx="0.000573" iyy="0.000573" izz="0.00098" ixy="0" ixz="0" iyz="0"/>
    </inertial>
  </link>
  <link name="rocker_right">
    <visual>
      <origin xyz="0 0.11 0" rpy="0 0 0"/>
      <geometry>
        <cylinder radius="0.015" length="0.22"/>
      </geometry>
      <material name="silver">
        <color rgba="0.7 0.7 0.7 1"/>
      </material>
    </visual>
    <collision>
      <origin xyz="0 0.11 0" rpy="0 0 0"/>
      <geometry>
        <cylinder radius="0.015" length="0.22"/>
      </geometry>
    </collision>
    <inertial>
      <origin xyz="0 0 0" rpy="0 0 0"/>
      <mass value="0.15"/>
      <inertia ixx="0.000613" iyy="0.000613" izz="1.7e-05" ixy="0" ixz="0" iyz="0"/>
    </inertial>
  </link>
  <link name="bogie_right">
    <visual>
      <origin xyz="0 0.09 0" rpy="0 0 0"/>
      <geometry>
        <cylinder radius="0.015" length="0.18"/>
      </geometry>
      <material name="silver">
        <color rgba="0.7 0.7 0.7 1"/>
      </material>
    </visual>
    <collision>
      <origin xyz="0 0.09 0" rpy="0 0 0"/>
      <geometry>
        <cylinder radius="0.015" length="0.18"/>
      </geometry>
    </collision>
    <inertial>
      <origin xyz="0 0 0" rpy="0 0 0"/>
      <mass value="0.15"/>
      <inertia ixx="0.000413" iyy="0.000413" izz="1.7e-05" ixy="0" ixz="0" iyz="0"/>
    </inertial>
  </link>
  <link name="wheel_front_right">
    <visual>
      <origin xyz="0 0 0" rpy="1.5708 0 0"/>
      <geometry>
        <cylinder radius="0.07" length="0.05"/>
      </geometry>
      <material name="rubber">
        <color rgba="0.15 0.15 0.15 1"/>
      </material>
    </visual>
    <visual>
      <origin xyz="0 0 0" rpy="1.5708 0 0"/>
      <geometry>
        <cylinder radius="0.076" length="0.025"/>
      </geometry>
      <material name="tread">
        <color rgba="0.08 0.08 0.08 1"/>
      </material>
    </visual>
    <collision>
      <origin xyz="0 0 0" rpy="1.5708 0 0"/>
      <geometry>
        <cylinder radius="0.07" length="0.05"/>
      </geometry>
    </collision>
    <inertial>
      <origin xyz="0 0 0" rpy="0 0 0"/>
      <mass value="0.4"/>
      <inertia ixx="0.000573" iyy="0.000573" izz="0.00098" ixy="0" ixz="0" iyz="0"/>
    </inertial>
  </link>
  <link name="wheel_mid_right">
    <visual>
      <origin xyz="0 0 0" rpy="1.5708 0 0"/>
      <geometry>
        <cylinder radius="0.07" length="0.05"/>
      </geometry>
      <material name="rubber">
        <color rgba="0.15 0.15 0.15 1"/>
      </material>
    </visual>
    <visual>
      <origin xyz="0 0 0" rpy="1.5708 0 0"/>
      <geometry>
        <cylinder radius="0.076" length="0.025"/>
      </geometry>
      <material name="tread">
        <color rgba="0.08 0.08 0.08 1"/>
      </material>
    </visual>
    <collision>
      <origin xyz="0 0 0" rpy="1.5708 0 0"/>
      <geometry>
        <cylinder radius="0.07" length="0.05"/>
      </geometry>
    </collision>
    <inertial>
      <origin xyz="0 0 0" rpy="0 0 0"/>
      <mass value="0.4"/>
      <inertia ixx="0.000573" iyy="0.000573" izz="0.00098" ixy="0" ixz="0" iyz="0"/>
    </inertial>
  </link>
  <link name="wheel_rear_right">
    <visual>
      <origin xyz="0 0 0" rpy="1.5708 0 0"/>
      <geometry>
        <cylinder radius="0.07" length="0.05"/>
      </geometry>
      <material name="rubber">
        <color rgba="0.15 0.15 0.15 1"/>
      </material>
    </visual>
    <visual>
      <origin xyz="0 0 0" rpy="1.5708 0 0"/>
      <geometry>
        <cylinder radius="0.076" length="0.025"/>
      </geometry>
      <material name="tread">
        <color rgba="0.08 0.08 0.08 1"/>
      </material>
    </visual>
    <collision>
      <origin xyz="0 0 0" rpy="1.5708 0 0"/>
      <geometry>
        <cylinder radius="0.07" length="0.05"/>
      </geometry>
    </collision>
    <inertial>
      <origin xyz="0 0 0" rpy="0 0 0"/>
      <mass value="0.4"/>
      <inertia ixx="0.000573" iyy="0.000573" izz="0.00098" ixy="0" ixz="0" iyz="0"/>
    </inertial>
  </link>
  <joint name="mast_joint" type="fixed">
    <parent link="base_link"/>
    <child link="mast_link"/>
    <origin xyz="0 0.11 0.16" rpy="0 0 0"/>
  </joint>
  <joint name="rocker_left_joint" type="revolute">
    <parent link="base_link"/>
    <child link="rocker_left"/>
    <origin xyz="-0.25 0.108 -0.075" rpy="0 0 0"/>
    <axis xyz="1 0 0"/>
    <limit lower="-0.52" upper="0.52" effort="0" velocity="1"/>
    <dynamics damping="0.5" friction="0.0"/>
  </joint>
  <joint name="wheel_front_left_joint" type="continuous">
    <parent link="rocker_left"/>
    <child link="wheel_front_left"/>
    <origin xyz="-0.025 0.072 -0.075" rpy="0 0 0"/>
    <axis xyz="0 1 0"/>
    <dynamics damping="0.05" friction="0.1"/>
    <limit effort="10" velocity="20" lower="-1e9" upper="1e9"/>
  </joint>
  <joint name="bogie_left_joint" type="revolute">
    <parent link="rocker_left"/>
    <child link="bogie_left"/>
    <origin xyz="0 -0.11 0" rpy="0 0 0"/>
    <axis xyz="1 0 0"/>
    <limit lower="-0.52" upper="0.52" effort="0" velocity="1"/>
    <dynamics damping="0.5" friction="0.0"/>
  </joint>
  <joint name="wheel_mid_left_joint" type="continuous">
    <parent link="bogie_left"/>
    <child link="wheel_mid_left"/>
    <origin xyz="-0.025 0.09 -0.09" rpy="0 0 0"/>
    <axis xyz="0 1 0"/>
    <dynamics damping="0.05" friction="0.1"/>
    <limit effort="10" velocity="20" lower="-1e9" upper="1e9"/>
  </joint>
  <joint name="wheel_rear_left_joint" type="continuous">
    <parent link="bogie_left"/>
    <child link="wheel_rear_left"/>
    <origin xyz="-0.025 -0.09 -0.09" rpy="0 0 0"/>
    <axis xyz="0 1 0"/>
    <dynamics damping="0.05" friction="0.1"/>
    <limit effort="10" velocity="20" lower="-1e9" upper="1e9"/>
  </joint>
  <joint name="rocker_right_joint" type="revolute">
    <parent link="base_link"/>
    <child link="rocker_right"/>
    <origin xyz="0.25 0.108 -0.075" rpy="0 0 0"/>
    <axis xyz="1 0 0"/>
    <limit lower="-0.52" upper="0.52" effort="0" velocity="1"/>
    <dynamics damping="0.5" friction="0.0"/>
  </joint>
  <joint name="wheel_front_right_joint" type="continuous">
    <parent link="rocker_right"/>
    <child link="wheel_front_right"/>
    <origin xyz="0.025 0.072 -0.075" rpy="0 0 0"/>
    <axis xyz="0 1 0"/>
    <dynamics damping="0.05" friction="0.1"/>
    <limit effort="10" velocity="20" lower="-1e9" upper="1e9"/>
  </joint>
  <joint name="bogie_right_joint" type="revolute">
    <parent link="rocker_right"/>
    <child link="bogie_right"/>
    <origin xyz="0 -0.11 0" rpy="0 0 0"/>
    <axis xyz="1 0 0"/>
    <limit lower="-0.52" upper="0.52" effort="0" velocity="1"/>
    <dynamics damping="0.5" friction="0.0"/>
  </joint>
  <joint name="wheel_mid_right_joint" type="continuous">
    <parent link="bogie_right"/>
    <child link="wheel_mid_right"/>
    <origin xyz="0.025 0.09 -0.09" rpy="0 0 0"/>
    <axis xyz="0 1 0"/>
    <dynamics damping="0.05" friction="0.1"/>
    <limit effort="10" velocity="20" lower="-1e9" upper="1e9"/>
  </joint>
  <joint name="wheel_rear_right_joint" type="continuous">
    <parent link="bogie_right"/>
    <child link="wheel_rear_right"/>
    <origin xyz="0.025 -0.09 -0.09" rpy="0 0 0"/>
    <axis xyz="0 1 0"/>
    <dynamics damping="0.05" friction="0.1"/>
    <limit effort="10" velocity="20" lower="-1e9" upper="1e9"/>
  </joint>
</robot>
